<?xml version="1.0" encoding="utf-8"?>
<!-- This URDF was automatically created by SolidWorks to URDF Exporter! Originally created by Stephen Brawner (brawner@gmail.com) 
     Commit Version: 1.6.0-4-g7f85cfe  Build Version: 1.6.7995.38578
     For more information, please see http://wiki.ros.org/sw_urdf_exporter -->
<robot
  name="piper_description">
  <link
    name="base_link">
    <inertial>
      <origin
        xyz="-0.00975190087285574 5.34726129873926E-05 0.0410165234196948"
        rpy="0 0 0" />
      <mass
        value="0.162290652295194" />
      <inertia
        ixx="0.000160479830657069"
        ixy="2.07749341071195E-07"
        ixz="7.30880977055225E-06"
        iyy="0.000177543818126594"
        iyz="2.64353979929137E-07"
        izz="0.000196275790067587" />
    </inertial>
    <visual>
      <origin
        xyz="0 0 0"
        rpy="0 0 0" />
      <geometry>
        <mesh
          filename="package://piper_description/meshes/base_link.STL" />
      </geometry>
      <material
        name="">
        <color
          rgba="0.250980392156863 0.250980392156863 0.250980392156863 1" />
      </material>
    </visual>
    <collision>
      <origin
        xyz="0 0 0"
        rpy="0 0 0" />
      <geometry>
        <mesh
          filename="package://piper_description/meshes/base_link.STL" />
      </geometry>
    </collision>
  </link>
  <link
    name="link1">
    <inertial>
      <origin
        xyz="0.000375551090544178 0.00112088387102302 0.025926439061327"
        rpy="0 0 0" />
      <mass
        value="0.106878894462235" />
      <inertia
        ixx="9.22238471272475E-05"
        ixy="2.34302850415048E-07"
        ixz="2.47717336872312E-07"
        iyy="7.78829507845198E-05"
        iyz="2.61560177110062E-06"
        izz="8.34708313944142E-05" />
    </inertial>
    <visual>
      <origin
        xyz="0 0 0"
        rpy="0 0 0" />
      <geometry>
        <mesh
          filename="package://piper_description/meshes/link1.STL" />
      </geometry>
      <material
        name="">
        <color
          rgba="0.250980392156863 0.250980392156863 0.250980392156863 1" />
      </material>
    </visual>
    <collision>
      <origin
        xyz="0 0 0"
        rpy="0 0 0" />
      <geometry>
        <mesh
          filename="package://piper_description/meshes/link1.STL" />
      </geometry>
    </collision>
  </link>
  <joint
    name="joint1"
    type="revolute">
    <origin
      xyz="0 0 0.08595"
      rpy="0 0 0" />
    <parent
      link="base_link" />
    <child
      link="link1" />
    <axis
      xyz="0 0 1" />
    <limit
      lower="-2.618"
      upper="2.618"
      effort="100"
      velocity="5" />
  </joint>
  <link
    name="link2">
    <inertial>
      <origin
        xyz="0.150518491992277 -0.000547924417337114 -0.0250920255693357"
        rpy="0 0 0" />
      <mass
        value="0.203932846071332" />
      <inertia
        ixx="0.000232128709565741"
        ixy="-7.6139452556297E-05"
        ixz="-4.23018844728719E-06"
        iyy="0.0016987612964322"
        iyz="-6.76991359522416E-06"
        izz="0.00162743101884687" />
    </inertial>
    <visual>
      <origin
        xyz="0 0 0"
        rpy="0 0 0" />
      <geometry>
        <mesh
          filename="package://piper_description/meshes/link2.STL" />
      </geometry>
      <material
        name="">
        <color
          rgba="1 1 1 1" />
      </material>
    </visual>
    <collision>
      <origin
        xyz="0 0 0"
        rpy="0 0 0" />
      <geometry>
        <mesh
          filename="package://piper_description/meshes/link2.STL" />
      </geometry>
    </collision>
  </link>
  <joint
    name="joint2"
    type="revolute">
    <origin
      xyz="0 0.03275 0.035"
      rpy="1.5708 0 3.1416" />
    <parent
      link="link1" />
    <child
      link="link2" />
    <axis
      xyz="0 0 1" />
    <limit
      lower="0"
      upper="3.14"
      effort="100"
      velocity="5" />
  </joint>
  <link
    name="link3">
    <inertial>
      <origin
        xyz="-0.102045660243796 -0.024114542066025 0.0323164387579708"
        rpy="0 0 0" />
      <mass
        value="0.259293309425469" />
      <inertia
        ixx="9.72940928229208E-05"
        ixy="-1.52464407164653E-05"
        ixz="-9.99813206259304E-07"
        iyy="0.000182575130849435"
        iyz="-5.84421248528308E-07"
        izz="0.000209232673676098" />
    </inertial>
    <visual>
      <origin
        xyz="0 0 0"
        rpy="0 0 0" />
      <geometry>
        <mesh
          filename="package://piper_description/meshes/link3.STL" />
      </geometry>
      <material
        name="">
        <color
          rgba="1 1 1 1" />
      </material>
    </visual>
    <collision>
      <origin
        xyz="0 0 0"
        rpy="0 0 0" />
      <geometry>
        <mesh
          filename="package://piper_description/meshes/link3.STL" />
      </geometry>
    </collision>
  </link>
  <joint
    name="joint3"
    type="revolute">
    <origin
      xyz="0.28358 0.028726 0"
      rpy="-3.1416 0 0" />
    <parent
      link="link2" />
    <child
      link="link3" />
    <axis
      xyz="0 0 1" />
    <limit
      lower="0"
      upper="2.967"
      effort="100"
      velocity="5" />
  </joint>
  <link
    name="link4">
    <inertial>
      <origin
        xyz="0.000201744435594647 0.00107635864162487 0.0312093093757311"
        rpy="0 0 0" />
      <mass
        value="0.1207071468194" />
      <inertia
        ixx="3.66188721202737E-05"
        ixy="-4.38560672722882E-08"
        ixz="4.65263091874631E-08"
        iyy="4.59015964823145E-05"
        iyz="6.84949419456508E-08"
        izz="3.90050566107364E-05" />
    </inertial>
    <visual>
      <origin
        xyz="0 0 0"
        rpy="0 0 0" />
      <geometry>
        <mesh
          filename="package://piper_description/meshes/link4.STL" />
      </geometry>
      <material
        name="">
        <color
          rgba="0.250980392156863 0.250980392156863 0.250980392156863 1" />
      </material>
    </visual>
    <collision>
      <origin
        xyz="0 0 0"
        rpy="0 0 0" />
      <geometry>
        <mesh
          filename="package://piper_description/meshes/link4.STL" />
      </geometry>
    </collision>
  </link>
  <joint
    name="joint4"
    type="revolute">
    <origin
      xyz="-0.21102 -0.040531 0.03275"
      rpy="1.5708 0 -1.4835" />
    <parent
      link="link3" />
    <child
      link="link4" />
    <axis
      xyz="0 0 1" />
    <limit
      lower="-1.745"
      upper="1.745"
      effort="100"
      velocity="5" />
  </joint>
  <link
    name="link5">
    <inertial>
      <origin
        xyz="4.0273336060076E-05 -0.0573381961330994 -0.0201925080862555"
        rpy="0 0 0" />
      <mass
        value="0.136390779513211" />
      <inertia
        ixx="0.000120317058116666"
        ixy="-2.87236059393685E-07"
        ixz="4.25662222687394E-08"
        iyy="6.55779819252321E-05"
        iyz="-2.42652201460275E-05"
        izz="0.000114207201784563" />
    </inertial>
    <visual>
      <origin
        xyz="0 0 0"
        rpy="0 0 0" />
      <geometry>
        <mesh
          filename="package://piper_description/meshes/link5.STL" />
      </geometry>
      <material
        name="">
        <color
          rgba="1 1 1 1" />
      </material>
    </visual>
    <collision>
      <origin
        xyz="0 0 0"
        rpy="0 0 0" />
      <geometry>
        <mesh
          filename="package://piper_description/meshes/link5.STL" />
      </geometry>
    </collision>
  </link>
  <joint
    name="joint5"
    type="revolute">
    <origin
      xyz="0 0.02392 0.036"
      rpy="-1.5708 0 0" />
    <parent
      link="link4" />
    <child
      link="link5" />
    <axis
      xyz="0 0 1" />
    <limit
      lower="-1.74"
      upper="1.74"
      effort="100"
      velocity="5" />
  </joint>
  <link
    name="link6">
    <inertial>
      <origin
        xyz="0.00586377457744311 0.00279283034634777 0.057640881586682"
        rpy="0 0 0" />
      <mass
        value="0.297734657028244" />
      <inertia
        ixx="0.000271695365544578"
        ixy="-6.03787718315E-07"
        ixz="-1.78359176368329E-06"
        iyy="0.000159035071134233"
        iyz="2.74636108273963E-06"
        izz="0.000189363658346074" />
    </inertial>
    <visual>
      <origin
        xyz="0 0 0"
        rpy="0 0 0" />
      <geometry>
        <mesh
          filename="package://piper_description/meshes/link6.STL" />
      </geometry>
      <material
        name="">
        <color
          rgba="0.752941176470588 0.752941176470588 0.752941176470588 1" />
      </material>
    </visual>
    <collision>
      <origin
        xyz="0 0 0"
        rpy="0 0 0" />
      <geometry>
        <mesh
          filename="package://piper_description/meshes/link6.STL" />
      </geometry>
    </collision>
  </link>
  <joint
    name="joint6"
    type="revolute">
    <origin
      xyz="0 -0.091 -0.02392"
      rpy="1.5708 0 0" />
    <parent
      link="link5" />
    <child
      link="link6" />
    <axis
      xyz="0 0 1" />
    <limit
      lower="-2.0944"
      upper="2.0944"
      effort="100"
      velocity="3" />
  </joint>
</robot>